Traceback (most recent call last):
  File "/Users/e30737/miniconda3/envs/py310/lib/python3.10/site-packages/jupyter_cache/executors/utils.py", line 58, in single_nb_execution
    executenb(
  File "/Users/e30737/miniconda3/envs/py310/lib/python3.10/site-packages/nbclient/client.py", line 1204, in execute
    return NotebookClient(nb=nb, resources=resources, km=km, **kwargs).execute()
  File "/Users/e30737/miniconda3/envs/py310/lib/python3.10/site-packages/nbclient/util.py", line 84, in wrapped
    return just_run(coro(*args, **kwargs))
  File "/Users/e30737/miniconda3/envs/py310/lib/python3.10/site-packages/nbclient/util.py", line 62, in just_run
    return loop.run_until_complete(coro)
  File "/Users/e30737/miniconda3/envs/py310/lib/python3.10/asyncio/base_events.py", line 649, in run_until_complete
    return future.result()
  File "/Users/e30737/miniconda3/envs/py310/lib/python3.10/site-packages/nbclient/client.py", line 663, in async_execute
    await self.async_execute_cell(
  File "/Users/e30737/miniconda3/envs/py310/lib/python3.10/site-packages/nbclient/client.py", line 965, in async_execute_cell
    await self._check_raise_for_error(cell, cell_index, exec_reply)
  File "/Users/e30737/miniconda3/envs/py310/lib/python3.10/site-packages/nbclient/client.py", line 862, in _check_raise_for_error
    raise CellExecutionError.from_cell_and_msg(cell, exec_reply_content)
nbclient.exceptions.CellExecutionError: An error occurred while executing the following cell:
------------------
# start times
utime_1d = utime[:,0]

# midpoints
utime_1d = np.mean(utime, axis=1)
------------------

[0;31m---------------------------------------------------------------------------[0m
[0;31mNameError[0m                                 Traceback (most recent call last)
Cell [0;32mIn[8], line 5[0m
[1;32m      2[0m utime_1d [38;5;241m=[39m utime[:,[38;5;241m0[39m]
[1;32m      4[0m [38;5;66;03m# midpoints[39;00m
[0;32m----> 5[0m utime_1d [38;5;241m=[39m [43mnp[49m[38;5;241m.[39mmean(utime, axis[38;5;241m=[39m[38;5;241m1[39m)

[0;31mNameError[0m: name 'np' is not defined
NameError: name 'np' is not defined

